Workbook

Sheet Mode d'emploi
A1: Vélora Flex — budget sur 18 mois · modèle à compléter
A2: Cours Business models et budgétisation · cas fictif, hypothèses pédagogiques
A4: 1. Onglet Hypothèses : vérifiez les données du cas, saisissez vos choix (option de plateforme, réserve de vélos, achat ou location, rythme d'acquisition), puis calculez les valeurs dérivées.
A5: 2. Onglet Budget mensualisé : remplissez chaque ligne mois par mois, uniquement par des formules qui renvoient à l'onglet Hypothèses. Aucun chiffre saisi en dur.
A6: 3. Pour chaque ligne, indiquez Fixe ou Variable, CAPEX ou OPEX, et l'hypothèse ou la formule utilisée. La ligne « Chef de projet » est déjà remplie à titre d'exemple.
A7: 4. Ordre conseillé : abonnés (activité), revenus, flotte, plateforme, RH, média, exploitation. Les sous-totaux, totaux et cumuls se calculent seuls.
A8: 5. Onglet Synthèse : lisez le total par compartiment, l'écart avec l'enveloppe de 1,1 M€ et le mois où l'exploitation devient positive. Complétez le point mort.
A9: 6. Bloc 4 : onglets Scénarios (trois chocs), Risques (registre et provision) et Pilotage M9 (écarts et coût à terminaison).
A10: 7. Onglet BMC : les deux Business Model Canvas de l'exercice 1 du bloc 1.
A11: Contrôles utiles : abonnés actifs au mois 18 = objectif ; flotte = abonnés actifs + réserve ; total des coûts = somme des sous-totaux.
A13: Légende
A14: Cellule jaune : à remplir par le groupe (valeur ou formule)
... A17: Texte vert : valeur reprise d'un autre onglet

Sheet Hypothèses
A1: Hypothèses
A2: Toutes les lignes du budget doivent renvoyer à cet onglet
A4: Hypothèse | B4: Valeur | C4: Unité | D4: Source ou commentaire
A5: Données du cas (fiche Vélora Flex)
A6: Prix de l'abonnement | B6: 49 | C6: € HT par mois | D6: Donnée du cas
A7: Objectif d'abonnés actifs en fin d'horizon | B7: 1200 | C7: abonnés | D7: Donnée du cas
A8: Horizon du projet | B8: 18 | C8: mois | D8: Donnée du cas
A9: Mois du lancement commercial | B9: 4 | C9: n° de mois | D9: Donnée du cas
A10: Résiliation mensuelle (churn) | B10: 0.04 | C10: % par mois | D10: Donnée du cas
A11: Coût de revient d'un vélo | B11: 600 | C11: € | D11: Donnée du cas
A12: Durée d'usage d'un vélo | B12: 36 | C12: mois | D12: Donnée du cas (3 ans)
A13: Entretien et assurance | B13: 9 | C13: € par abonné et par mois | D13: Donnée du cas
A14: Plateforme A : charge de développement | B14: 120 | C14: jours-homme | D14: Donnée du cas
A15: Plateforme A : TJM de l'agence | B15: 650 | C15: € par jour | D15: Donnée du cas
A16: Plateforme A : maintenance annuelle | B16: 0.15 | C16: % du développement | D16: Donnée du cas
A17: Plateforme B : abonnement SaaS | B17: 1500 | C17: € par mois | D17: Donnée du cas
... A28: Enveloppe maximale, flotte comprise | B28: 1100000 | C28: € | D28: Donnée du cas
A30: Choix du groupe
A31: Option de plateforme (A = sur mesure, B = SaaS) | B31: B | C31: A ou B | D31: SaaS retenu : aucune mise de départ, un coût qui suit l'activité. Sur 18 mois il coûte environ 37 k€ contre 93 k€ pour le sur mesure, dont le payback est de 46 mois (exercice 3)
A32: Vélos de réserve (atelier, vols, casse) | B32: 60 | C32: vélos | D32: 5 % de l'objectif : vélos en révision à l'atelier, ou en remplacement après un vol ou une casse
A33: Plafond de vélos achetés (au-delà, les vélos sont loués) | B33: 600 | C33: vélos | D33: Socle acheté : 600 vélos × 600 € = 360 k€. Au-delà, location : la flotte suit les abonnés, se rend si la montée en charge déçoit, et le budget tient dans l'enveloppe
A34: Loyer mensuel d'un vélo loué | B34: 25 | C34: € par vélo et par mois | D34: Hypothèse du groupe : location longue durée d'un vélo nu (entretien et assurance déjà comptés à 9 €). Plus cher que l'amortissement (16,67 €) : c'est le prix de la souplesse
A35: Nouveaux abonnés par mois (vide = calculé pour atteindre l'objectif) | C35: abonnés par mois | D35: Laissé vide : calculé pour atteindre l'objectif au mois 18 (valeur en B46)
A36: Provision pour aléas | B36: =Risques!D10 | C36: € | D36: Somme des valeurs attendues du registre des risques (onglet Risques), répartie sur 18 mois dans le budget
A38: Pilotage des versions
A39: Scénario actif (1 à 5, onglet Scénarios) | B39: 1 | C39: n° | D39: 1 = référence. Bloc 4 : passer à 2, 3, 4 ou 5 pour le stress-test, relever l'onglet Synthèse, puis revenir à 1
A40: Version du budget (1 = initiale, 2 = après coupe du DAF) | B40: 1 | C40: n° | D40: Bloc 2 : la version 2 applique les leviers de l'onglet Coupe DAF (lignes 64 à 67)
A44: Valeurs calculées
A45: Nombre de mois commerciaux | B45: =$B$8-$B$71+1 | C45: mois | D45: Horizon − mois de lancement appliqué + 1
A46: Nouveaux abonnés par mois | B46: =IF(ISBLANK($B$35),$B$73*$B$72/(1-(1-$B$72)^$B$45),$B$35) | C46: abonnés par mois | D46: Objectif appliqué × churn ÷ (1 − (1 − churn) puissance nombre de mois)
A47: Coût d'acquisition (CAC) | B47: =$B$70/$B$27 | C47: € par abonné | D47: CPC appliqué ÷ taux de conversion
A48: Chef de projet : coût mensuel chargé | B48: =B19*B25/12 | C48: € par mois | D48: Exemple déjà rempli : brut × coefficient ÷ 12
A49: Responsable marketing : coût mensuel chargé | B49: =B20*B21*B25/12 | C49: € par mois | D49: Brut × quotité × coefficient ÷ 12
A50: Techniciens : coût mensuel chargé | B50: =B22*B23*B25/12 | C50: € par mois | D50: Brut × nombre × coefficient ÷ 12
A51: Plateforme A : coût de développement | B51: =B14*B15 | C51: € | D51: Jours-homme × TJM
A52: Plateforme A : maintenance mensuelle | B52: =B51*B16/12 | C52: € par mois | D52: Développement × 15 % ÷ 12
A53: Marge par abonné, avant coût du vélo | B53: =B6-B13 | C53: € par mois | D53: Prix − entretien et assurance
A54: Amortissement mensuel d'un vélo | B54: =B11/B12 | C54: € par mois | D54: Coût de revient ÷ durée d'usage
A56: Hypothèses supplémentaires du groupe
A57: Outils marketing (CRM, emailing, analytics) | B57: 250 | C57: € par mois | D57: Hypothèse du groupe, à partir du mois qui précède le lancement
...

Sheet Budget mensualisé
A1: Budget mensualisé sur 18 mois (€ HT)
A2: Une ligne par poste, une colonne par mois · chaque ligne renvoie à l'onglet Hypothèses
A3: Mois n° | E3: 1 | F3: 2 | G3: 3 | H3: 4 | I3: 5 | J3: 6 | K3: 7 | L3: 8 | M3: 9 | N3: 10 | O3: 11 | P3: 12 | Q3: 13 | R3: 14 | S3: 15 | T3: 16 | U3: 17 | V3: 18
A4: Rubrique | B4: Fixe ou variable | C4: CAPEX ou OPEX | D4: Hypothèse ou formule utilisée | E4: M1 | F4: M2 | G4: M3 | H4: M4 | I4: M5 | J4: M6 | K4: M7 | L4: M8 | M4: M9 | N4: M10 | O4: M11 | P4: M12 | Q4: M13 | R4: M14 | S4: M15 | T4: M16 | U4: M17 | V4: M18 | W4: Total
A5: ACTIVITÉ
A6: Nouveaux abonnés | D6: Nouveaux abonnés par mois (Hypothèses B46) dès le mois de lancement | E6: =IF(E$3>=Hypothèses!$B$71,Hypothèses!$B$46,0) | F6: =IF(F$3>=Hypothèses!$B$71,Hypothèses!$B$46,0) | G6: =IF(G$3>=Hypothèses!$B$71,Hypothèses!$B$46,0) | H6: =IF(H$3>=Hypothèses!$B$71,Hypothèses!$B$46,0) | I6: =IF(I$3>=Hypothèses!$B$71,Hypothèses!$B$46,0) | J6: =IF(J$3>=Hypothèses!$B$71,Hypothèses!$B$46,0) | K6: =IF(K$3>=Hypothèses!$B$71,Hypothèses!$B$46,0) | L6: =IF(L$3>=Hypothèses!$B$71,Hypothèses!$B$46,0) | ... V6: =IF(V$3>=Hypothèses!$B$71,Hypothèses!$B$46,0) | W6: =SUM(E6:V6)
A7: Résiliations | D7: Abonnés actifs du mois précédent × churn | E7: =N(D8)*Hypothèses!$B$72 | F7: =N(E8)*Hypothèses!$B$72 | G7: =N(F8)*Hypothèses!$B$72 | H7: =N(G8)*Hypothèses!$B$72 | I7: =N(H8)*Hypothèses!$B$72 | J7: =N(I8)*Hypothèses!$B$72 | K7: =N(J8)*Hypothèses!$B$72 | L7: =N(K8)*Hypothèses!$B$72 | ... V7: =N(U8)*Hypothèses!$B$72 | W7: =SUM(E7:V7)
A8: Abonnés actifs en fin de mois | D8: Actifs du mois précédent − résiliations + nouveaux | E8: =N(D8)-E7+E6 | F8: =N(E8)-F7+F6 | G8: =N(F8)-G7+G6 | H8: =N(G8)-H7+H6 | I8: =N(H8)-I7+I6 | J8: =N(I8)-J7+J6 | K8: =N(J8)-K7+K6 | L8: =N(K8)-L7+L6 | ... V8: =N(U8)-V7+V6 | W8: =V8
A9: Vélos en flotte (achetés et loués) | D9: Abonnés actifs + réserve dès le lancement ; la flotte ne diminue jamais | E9: =IF(E$3>=Hypothèses!$B$71,MAX(N(D9),E8+Hypothèses!$B$32),0) | F9: =IF(F$3>=Hypothèses!$B$71,MAX(N(E9),F8+Hypothèses!$B$32),0) | G9: =IF(G$3>=Hypothèses!$B$71,MAX(N(F9),G8+Hypothèses!$B$32),0) | H9: =IF(H$3>=Hypothèses!$B$71,MAX(N(G9),H8+Hypothèses!$B$32),0) | I9: =IF(I$3>=Hypothèses!$B$71,MAX(N(H9),I8+Hypothèses!$B$32),0) | J9: =IF(J$3>=Hypothèses!$B$71,MAX(N(I9),J8+Hypothèses!$B$32),0) | K9: =IF(K$3>=Hypothèses!$B$71,MAX(N(J9),K8+Hypothèses!$B$32),0) | L9: =IF(L$3>=Hypothèses!$B$71,MAX(N(K9),L8+Hypothèses!$B$32),0) | ... V9: =IF(V$3>=Hypothèses!$B$71,MAX(N(U9),V8+Hypothèses!$B$32),0) | W9: =V9
A10: dont vélos loués | D10: Flotte − plafond de vélos achetés | E10: =MAX(0,E9-Hypothèses!$B$74) | F10: =MAX(0,F9-Hypothèses!$B$74) | G10: =MAX(0,G9-Hypothèses!$B$74) | H10: =MAX(0,H9-Hypothèses!$B$74) | I10: =MAX(0,I9-Hypothèses!$B$74) | J10: =MAX(0,J9-Hypothèses!$B$74) | K10: =MAX(0,K9-Hypothèses!$B$74) | L10: =MAX(0,L9-Hypothèses!$B$74) | ... V10: =MAX(0,V9-Hypothèses!$B$74) | W10: =V10
A11: REVENUS
A12: Abonnements | B12: Variable | D12: Abonnés actifs en fin de mois × 49 € HT | E12: =E8*Hypothèses!$B$6 | F12: =F8*Hypothèses!$B$6 | G12: =G8*Hypothèses!$B$6 | H12: =H8*Hypothèses!$B$6 | I12: =I8*Hypothèses!$B$6 | J12: =J8*Hypothèses!$B$6 | K12: =K8*Hypothèses!$B$6 | L12: =L8*Hypothèses!$B$6 | ... V12: =V8*Hypothèses!$B$6 | W12: =SUM(E12:V12)
A13: Autres revenus | D13: Aucun revenu annexe retenu, par prudence (frais de dossier, franchise vol : pistes non chiffrées) | W13: =SUM(E13:V13)
A14: Total des revenus | E14: =SUM(E12:E13) | F14: =SUM(F12:F13) | G14: =SUM(G12:G13) | H14: =SUM(H12:H13) | I14: =SUM(I12:I13) | J14: =SUM(J12:J13) | K14: =SUM(K12:K13) | L14: =SUM(L12:L13) | ... V14: =SUM(V12:V13) | W14: =SUM(E14:V14)
A15: FLOTTE
A16: Achat de vélos | B16: Variable | C16: CAPEX | D16: Vélos achetés dans le mois (jusqu'au plafond) × 600 € | E16: =(MIN(E9,Hypothèses!$B$74)-MIN(N(D9),Hypothèses!$B$74))*Hypothèses!$B$11 | F16: =(MIN(F9,Hypothèses!$B$74)-MIN(N(E9),Hypothèses!$B$74))*Hypothèses!$B$11 | G16: =(MIN(G9,Hypothèses!$B$74)-MIN(N(F9),Hypothèses!$B$74))*Hypothèses!$B$11 | H16: =(MIN(H9,Hypothèses!$B$74)-MIN(N(G9),Hypothèses!$B$74))*Hypothèses!$B$11 | I16: =(MIN(I9,Hypothèses!$B$74)-MIN(N(H9),Hypothèses!$B$74))*Hypothèses!$B$11 | J16: =(MIN(J9,Hypothèses!$B$74)-MIN(N(I9),Hypothèses!$B$74))*Hypothèses!$B$11 | K16: =(MIN(K9,Hypothèses!$B$74)-MIN(N(J9),Hypothèses!$B$74))*Hypothèses!$B$11 | L16: =(MIN(L9,Hypothèses!$B$74)-MIN(N(K9),Hypothèses!$B$74))*Hypothèses!$B$11 | ... V16: =(MIN(V9,Hypothèses!$B$74)-MIN(N(U9),Hypothèses!$B$74))*Hypothèses!$B$11 | W16: =SUM(E16:V16)
A17: Location de vélos | B17: Variable | C17: OPEX | D17: Vélos loués × loyer mensuel (25 €) | E17: =E10*Hypothèses!$B$34 | F17: =F10*Hypothèses!$B$34 | G17: =G10*Hypothèses!$B$34 | H17: =H10*Hypothèses!$B$34 | I17: =I10*Hypothèses!$B$34 | J17: =J10*Hypothèses!$B$34 | K17: =K10*Hypothèses!$B$34 | L17: =L10*Hypothèses!$B$34 | ... V17: =V10*Hypothèses!$B$34 | W17: =SUM(E17:V17)
A18: Sous-total flotte | E18: =SUM(E16:E17) | F18: =SUM(F16:F17) | G18: =SUM(G16:G17) | H18: =SUM(H16:H17) | I18: =SUM(I16:I17) | J18: =SUM(J16:J17) | K18: =SUM(K16:K17) | L18: =SUM(L16:L17) | ... V18: =SUM(V16:V17) | W18: =SUM(E18:V18)
A19: PLATEFORME ET OUTILS
A20: Développement sur mesure (option A) | B20: Fixe | C20: CAPEX | D20: Option A : 120 j × 650 €, réparti sur les mois de construction | E20: =IF(AND(Hypothèses!$B$31="A",E$3<Hypothèses!$B$71),Hypothèses!$B$51/(Hypothèses!$B$71-1),0) | F20: =IF(AND(Hypothèses!$B$31="A",F$3<Hypothèses!$B$71),Hypothèses!$B$51/(Hypothèses!$B$71-1),0) | G20: =IF(AND(Hypothèses!$B$31="A",G$3<Hypothèses!$B$71),Hypothèses!$B$51/(Hypothèses!$B$71-1),0) | H20: =IF(AND(Hypothèses!$B$31="A",H$3<Hypothèses!$B$71),Hypothèses!$B$51/(Hypothèses!$B$71-1),0) | I20: =IF(AND(Hypothèses!$B$31="A",I$3<Hypothèses!$B$71),Hypothèses!$B$51/(Hypothèses!$B$71-1),0) | J20: =IF(AND(Hypothèses!$B$31="A",J$3<Hypothèses!$B$71),Hypothèses!$B$51/(Hypothèses!$B$71-1),0) | K20: =IF(AND(Hypothèses!$B$31="A",K$3<Hypothèses!$B$71),Hypothèses!$B$51/(Hypothèses!$B$71-1),0) | L20: =IF(AND(Hypothèses!$B$31="A",L$3<Hypothèses!$B$71),Hypothèses!$B$51/(Hypothèses!$B$71-1),0) | ... V20: =IF(AND(Hypothèses!$B$31="A",V$3<Hypothèses!$B$71),Hypothèses!$B$51/(Hypothèses!$B$71-1),0) | W20: =SUM(E20:V20)
A21: Maintenance de la plateforme (option A) | B21: Fixe | C21: OPEX | D21: Option A : 15 % du développement par an ÷ 12, dès le lancement | E21: =IF(AND(Hypothèses!$B$31="A",E$3>=Hypothèses!$B$71),Hypothèses!$B$52,0) | F21: =IF(AND(Hypothèses!$B$31="A",F$3>=Hypothèses!$B$71),Hypothèses!$B$52,0) | G21: =IF(AND(Hypothèses!$B$31="A",G$3>=Hypothèses!$B$71),Hypothèses!$B$52,0) | H21: =IF(AND(Hypothèses!$B$31="A",H$3>=Hypothèses!$B$71),Hypothèses!$B$52,0) | I21: =IF(AND(Hypothèses!$B$31="A",I$3>=Hypothèses!$B$71),Hypothèses!$B$52,0) | J21: =IF(AND(Hypothèses!$B$31="A",J$3>=Hypothèses!$B$71),Hypothèses!$B$52,0) | K21: =IF(AND(Hypothèses!$B$31="A",K$3>=Hypothèses!$B$71),Hypothèses!$B$52,0) | L21: =IF(AND(Hypothèses!$B$31="A",L$3>=Hypothèses!$B$71),Hypothèses!$B$52,0) | ... V21: =IF(AND(Hypothèses!$B$31="A",V$3>=Hypothèses!$B$71),Hypothèses!$B$52,0) | W21: =SUM(E21:V21)
A22: Abonnement SaaS, part fixe (option B) | B22: Fixe | C22: OPEX | D22: Option B : 1 500 € par mois dès le mois 1 (paramétrage) | E22: =IF(Hypothèses!$B$31="B",Hypothèses!$B$17,0) | F22: =IF(Hypothèses!$B$31="B",Hypothèses!$B$17,0) | G22: =IF(Hypothèses!$B$31="B",Hypothèses!$B$17,0) | H22: =IF(Hypothèses!$B$31="B",Hypothèses!$B$17,0) | I22: =IF(Hypothèses!$B$31="B",Hypothèses!$B$17,0) | J22: =IF(Hypothèses!$B$31="B",Hypothèses!$B$17,0) | K22: =IF(Hypothèses!$B$31="B",Hypothèses!$B$17,0) | L22: =IF(Hypothèses!$B$31="B",Hypothèses!$B$17,0) | ... V22: =IF(Hypothèses!$B$31="B",Hypothèses!$B$17,0) | W22: =SUM(E22:V22)
A23: Commission SaaS sur le chiffre d'affaires (option B) | B23: Variable | C23: OPEX | D23: Option B : 2 % du chiffre d'affaires du mois | E23: =IF(Hypothèses!$B$31="B",E14*Hypothèses!$B$18,0) | F23: =IF(Hypothèses!$B$31="B",F14*Hypothèses!$B$18,0) | G23: =IF(Hypothèses!$B$31="B",G14*Hypothèses!$B$18,0) | H23: =IF(Hypothèses!$B$31="B",H14*Hypothèses!$B$18,0) | I23: =IF(Hypothèses!$B$31="B",I14*Hypothèses!$B$18,0) | J23: =IF(Hypothèses!$B$31="B",J14*Hypothèses!$B$18,0) | K23: =IF(Hypothèses!$B$31="B",K14*Hypothèses!$B$18,0) | L23: =IF(Hypothèses!$B$31="B",L14*Hypothèses!$B$18,0) | ... V23: =IF(Hypothèses!$B$31="B",V14*Hypothèses!$B$18,0) | W23: =SUM(E23:V23)
A24: Autres outils et licences | B24: Fixe | C24: OPEX | D24: Outils marketing (250 €), dès le mois qui précède le lancement | E24: =IF(E$3>=Hypothèses!$B$71-1,Hypothèses!$B$57,0) | F24: =IF(F$3>=Hypothèses!$B$71-1,Hypothèses!$B$57,0) | G24: =IF(G$3>=Hypothèses!$B$71-1,Hypothèses!$B$57,0) | H24: =IF(H$3>=Hypothèses!$B$71-1,Hypothèses!$B$57,0) | I24: =IF(I$3>=Hypothèses!$B$71-1,Hypothèses!$B$57,0) | J24: =IF(J$3>=Hypothèses!$B$71-1,Hypothèses!$B$57,0) | K24: =IF(K$3>=Hypothèses!$B$71-1,Hypothèses!$B$57,0) | L24: =IF(L$3>=Hypothèses!$B$71-1,Hypothèses!$B$57,0) | ... V24: =IF(V$3>=Hypothèses!$B$71-1,Hypothèses!$B$57,0) | W24: =SUM(E24:V24)
A25: Sous-total plateforme et outils | E25: =SUM(E20:E24) | F25: =SUM(F20:F24) | G25: =SUM(G20:G24) | H25: =SUM(H20:H24) | I25: =SUM(I20:I24) | J25: =SUM(J20:J24) | K25: =SUM(K20:K24) | L25: =SUM(L20:L24) | ... V25: =SUM(V20:V24) | W25: =SUM(E25:V25)
A26: RH INTERNES
A27: Chef de projet | B27: Fixe | C27: OPEX | D27: Brut × coefficient ÷ 12 | E27: =Hypothèses!$B$48 | F27: =Hypothèses!$B$48 | G27: =Hypothèses!$B$48 | H27: =Hypothèses!$B$48 | I27: =Hypothèses!$B$48 | J27: =Hypothèses!$B$48 | K27: =Hypothèses!$B$48 | L27: =Hypothèses!$B$48 | ... V27: =Hypothèses!$B$48 | W27: =SUM(E27:V27)
A28: Responsable marketing digital (mi-temps) | B28: Fixe | C28: OPEX | D28: Brut × mi-temps × coefficient ÷ 12 | E28: =Hypothèses!$B$49 | F28: =Hypothèses!$B$49 | G28: =Hypothèses!$B$49 | H28: =Hypothèses!$B$49 | I28: =Hypothèses!$B$49 | J28: =Hypothèses!$B$49 | K28: =Hypothèses!$B$49 | L28: =Hypothèses!$B$49 | ... V28: =Hypothèses!$B$49 | W28: =SUM(E28:V28)
A29: Techniciens | B29: Par paliers | C29: OPEX | D29: Coût chargé d'un technicien × techniciens embauchés à date | E29: =Hypothèses!$B$50/Hypothèses!$B$23*(IF(E$3>=Hypothèses!$B$24,1,0)+IF(E$3>=Hypothèses!$B$75,1,0)) | F29: =Hypothèses!$B$50/Hypothèses!$B$23*(IF(F$3>=Hypothèses!$B$24,1,0)+IF(F$3>=Hypothèses!$B$75,1,0)) | G29: =Hypothèses!$B$50/Hypothèses!$B$23*(IF(G$3>=Hypothèses!$B$24,1,0)+IF(G$3>=Hypothèses!$B$75,1,0)) | H29: =Hypothèses!$B$50/Hypothèses!$B$23*(IF(H$3>=Hypothèses!$B$24,1,0)+IF(H$3>=Hypothèses!$B$75,1,0)) | I29: =Hypothèses!$B$50/Hypothèses!$B$23*(IF(I$3>=Hypothèses!$B$24,1,0)+IF(I$3>=Hypothèses!$B$75,1,0)) | J29: =Hypothèses!$B$50/Hypothèses!$B$23*(IF(J$3>=Hypothèses!$B$24,1,0)+IF(J$3>=Hypothèses!$B$75,1,0)) | K29: =Hypothèses!$B$50/Hypothèses!$B$23*(IF(K$3>=Hypothèses!$B$24,1,0)+IF(K$3>=Hypothèses!$B$75,1,0)) | L29: =Hypothèses!$B$50/Hypothèses!$B$23*(IF(L$3>=Hypothèses!$B$24,1,0)+IF(L$3>=Hypothèses!$B$75,1,0)) | ... V29: =Hypothèses!$B$50/Hypothèses!$B$23*(IF(V$3>=Hypothèses!$B$24,1,0)+IF(V$3>=Hypothèses!$B$75,1,0)) | W29: =SUM(E29:V29)
A30: Sous-total RH internes | E30: =SUM(E27:E29) | F30: =SUM(F27:F29) | G30: =SUM(G27:G29) | H30: =SUM(H27:H29) | I30: =SUM(I27:I29) | J30: =SUM(J27:J29) | K30: =SUM(K27:K29) | L30: =SUM(L27:L29) | ... V30: =SUM(V27:V29) | W30: =SUM(E30:V30)
A31: PRESTATIONS EXTERNES
A32: Agence et freelances (hors plateforme) | B32: Fixe | C32: OPEX | D32: Production du lancement : 8 j × 650 €, le mois qui précède le lancement | E32: =IF(E$3=Hypothèses!$B$71-1,Hypothèses!$B$59*Hypothèses!$B$15,0) | F32: =IF(F$3=Hypothèses!$B$71-1,Hypothèses!$B$59*Hypothèses!$B$15,0) | G32: =IF(G$3=Hypothèses!$B$71-1,Hypothèses!$B$59*Hypothèses!$B$15,0) | H32: =IF(H$3=Hypothèses!$B$71-1,Hypothèses!$B$59*Hypothèses!$B$15,0) | I32: =IF(I$3=Hypothèses!$B$71-1,Hypothèses!$B$59*Hypothèses!$B$15,0) | J32: =IF(J$3=Hypothèses!$B$71-1,Hypothèses!$B$59*Hypothèses!$B$15,0) | K32: =IF(K$3=Hypothèses!$B$71-1,Hypothèses!$B$59*Hypothèses!$B$15,0) | L32: =IF(L$3=Hypothèses!$B$71-1,Hypothèses!$B$59*Hypothèses!$B$15,0) | ... V32: =IF(V$3=Hypothèses!$B$71-1,Hypothèses!$B$59*Hypothèses!$B$15,0) | W32: =SUM(E32:V32)
A33: Sous-total prestations externes | E33: =SUM(E32:E32) | F33: =SUM(F32:F32) | G33: =SUM(G32:G32) | H33: =SUM(H32:H32) | I33: =SUM(I32:I32) | J33: =SUM(J32:J32) | K33: =SUM(K32:K32) | L33: =SUM(L32:L32) | ... V33: =SUM(V32:V32) | W33: =SUM(E33:V33)
A34: MÉDIA ET ACQUISITION
A35: Achat média | B35: Variable | C35: OPEX | D35: Nouveaux abonnés × CAC (CPC ÷ conversion) | E35: =E6*Hypothèses!$B$47 | F35: =F6*Hypothèses!$B$47 | G35: =G6*Hypothèses!$B$47 | H35: =H6*Hypothèses!$B$47 | I35: =I6*Hypothèses!$B$47 | J35: =J6*Hypothèses!$B$47 | K35: =K6*Hypothèses!$B$47 | L35: =L6*Hypothèses!$B$47 | ... V35: =V6*Hypothèses!$B$47 | W35: =SUM(E35:V35)
A36: Création et contenus | B36: Fixe | C36: OPEX | D36: Forfait mensuel dès le mois qui précède le lancement | E36: =IF(E$3>=Hypothèses!$B$71-1,Hypothèses!$B$76,0) | F36: =IF(F$3>=Hypothèses!$B$71-1,Hypothèses!$B$76,0) | G36: =IF(G$3>=Hypothèses!$B$71-1,Hypothèses!$B$76,0) | H36: =IF(H$3>=Hypothèses!$B$71-1,Hypothèses!$B$76,0) | I36: =IF(I$3>=Hypothèses!$B$71-1,Hypothèses!$B$76,0) | J36: =IF(J$3>=Hypothèses!$B$71-1,Hypothèses!$B$76,0) | K36: =IF(K$3>=Hypothèses!$B$71-1,Hypothèses!$B$76,0) | L36: =IF(L$3>=Hypothèses!$B$71-1,Hypothèses!$B$76,0) | ... V36: =IF(V$3>=Hypothèses!$B$71-1,Hypothèses!$B$76,0) | W36: =SUM(E36:V36)
A37: Sous-total média et acquisition | E37: =SUM(E35:E36) | F37: =SUM(F35:F36) | G37: =SUM(G35:G36) | H37: =SUM(H35:H36) | I37: =SUM(I35:I36) | J37: =SUM(J35:J36) | K37: =SUM(K35:K36) | L37: =SUM(L35:L36) | ... V37: =SUM(V35:V36) | W37: =SUM(E37:V37)
A38: EXPLOITATION
A39: Entretien et assurance | B39: Variable | C39: OPEX | D39: Abonnés actifs × 9 € | E39: =E8*Hypothèses!$B$13 | F39: =F8*Hypothèses!$B$13 | G39: =G8*Hypothèses!$B$13 | H39: =H8*Hypothèses!$B$13 | I39: =I8*Hypothèses!$B$13 | J39: =J8*Hypothèses!$B$13 | K39: =K8*Hypothèses!$B$13 | L39: =L8*Hypothèses!$B$13 | ... V39: =V8*Hypothèses!$B$13 | W39: =SUM(E39:V39)
A40: Service client et divers | B40: Variable | C40: OPEX | D40: Frais de paiement : chiffre d'affaires × 1,5 % | E40: =E14*Hypothèses!$B$60 | F40: =F14*Hypothèses!$B$60 | G40: =G14*Hypothèses!$B$60 | H40: =H14*Hypothèses!$B$60 | I40: =I14*Hypothèses!$B$60 | J40: =J14*Hypothèses!$B$60 | K40: =K14*Hypothèses!$B$60 | L40: =L14*Hypothèses!$B$60 | ... V40: =V14*Hypothèses!$B$60 | W40: =SUM(E40:V40)
...

Sheet Synthèse
A1: Synthèse du budget
A2: Lue directement dans l'onglet Budget mensualisé
A4: Compartiment | B4: Total sur 18 mois (€) | C4: % des coûts
A5: Flotte | B5: ='Budget mensualisé'!W18 | C5: =IF($B$12=0,0,B5/$B$12)
A6: Plateforme et outils | B6: ='Budget mensualisé'!W25 | C6: =IF($B$12=0,0,B6/$B$12)
A7: RH internes | B7: ='Budget mensualisé'!W30 | C7: =IF($B$12=0,0,B7/$B$12)
A8: Prestations externes | B8: ='Budget mensualisé'!W33 | C8: =IF($B$12=0,0,B8/$B$12)
A9: Média et acquisition | B9: ='Budget mensualisé'!W37 | C9: =IF($B$12=0,0,B9/$B$12)
A10: Exploitation | B10: ='Budget mensualisé'!W41 | C10: =IF($B$12=0,0,B10/$B$12)
A11: Provision pour aléas | B11: ='Budget mensualisé'!W43 | C11: =IF($B$12=0,0,B11/$B$12)
A12: Total des coûts | B12: =SUM(B5:B11) | C12: =IF(B12=0,0,SUM(C5:C11))
A13: Contrôle : écart avec le total du budget (doit être 0) | B13: =B12-'Budget mensualisé'!W44
A15: Revenus cumulés | B15: ='Budget mensualisé'!W14
A16: Solde à 18 mois (revenus − coûts) | B16: =B15-B12
A17: Enveloppe maximale | B17: =Hypothèses!$B$28
A18: Écart avec l'enveloppe (positif = dépassement) | B18: =B12-B17
A19: Écart en % de l'enveloppe | B19: =IF(B17=0,0,B18/B17)
A21: Abonnés actifs au dernier mois | B21: ='Budget mensualisé'!W8
A22: Acquisitions cumulées | B22: ='Budget mensualisé'!W6
A23: Abonnés-mois cumulés | B23: =SUM('Budget mensualisé'!E8:V8)
A24: Vélos en flotte au dernier mois | B24: ='Budget mensualisé'!W9
A26: Total CAPEX | B26: =SUMIF('Budget mensualisé'!$C$16:$C$43,"CAPEX",'Budget mensualisé'!$W$16:$W$43) | D26: CAPEX et OPEX : lus dans la colonne C du budget, à renseigner ligne par ligne
A27: Total OPEX | B27: =SUMIF('Budget mensualisé'!$C$16:$C$43,"OPEX",'Budget mensualisé'!$W$16:$W$43)
A28: Total des coûts fixes | B28: =SUMIF('Budget mensualisé'!$B$16:$B$43,"Fixe",'Budget mensualisé'!$W$16:$W$43)+SUMIF('Budget mensualisé'!$B$16:$B$43,"Par paliers",'Budget mensualisé'!$W$16:$W$43) | D28: Fixe et variable : lus dans la colonne B du budget
A29: Total des coûts variables | B29: =SUMIF('Budget mensualisé'!$B$16:$B$43,"Variable",'Budget mensualisé'!$W$16:$W$43)
A31: Premier mois d'exploitation positive | B31: =IFERROR(MATCH(1,'Budget mensualisé'!E50:V50,0),"aucun")
A33: Point mort
A34: Coûts fixes mensuels en exploitation | B34: =Hypothèses!B48+Hypothèses!B49+Hypothèses!B50+IF(Hypothèses!B31="A",Hypothèses!B52,Hypothèses!B17) | C34: € par mois | D34: Équipe chargée + maintenance ou abonnement de la plateforme
A35: Marge par abonné, sans le vélo | B35: =Hypothèses!B53 | C35: € par mois | D35: Prix − entretien et assurance
A36: Point mort, sans le vélo | B36: =B34/B35 | C36: abonnés | D36: Coûts fixes ÷ marge par abonné
A37: Marge par abonné, avec l'amortissement du vélo | B37: =B35-Hypothèses!B54 | C37: € par mois | D37: Marge − coût du vélo ÷ durée d'usage
A38: Point mort, avec l'amortissement du vélo | B38: =B34/B37 | C38: abonnés | D38: Coûts fixes ÷ marge après amortissement
A39: Seuil mensuel, média compris | B39: =(B34+Hypothèses!B46*Hypothèses!B47)/B35 | C39: abonnés | D39: (Coûts fixes + média du mois) ÷ marge par abonné
A41: Lecture (version initiale, scénario de référence)
A42: Coûts sur 18 mois : 1 051 k€, soit 49 k€ (4,4 %) sous l'enveloppe de 1,1 M€, provision de 44 k€ comprise.
A43: Premier poste : la flotte (450 k€, 43 % des coûts), puis les RH internes (240 k€, 23 %) et le média (168 k€, 16 %).
A44: Revenus cumulés : 515 k€. Solde à 18 mois : − 536 k€, c'est l'investissement de lancement que finance l'enveloppe.
A45: Exploitation positive au mois 17, location des vélos comprise. Au mois 18 : 1 200 abonnés, 1 260 vélos (600 achetés, 660 loués).
A46: Point mort : 418 abonnés sans le vélo, 717 avec son amortissement, 658 en couvrant aussi le média du mois. Les deux derniers sont dépassés au mois 11.

Sheet Coupe DAF
A1: Le DAF coupe 15 % (bloc 2, mise en situation)
A2: Version 1 = budget initial, version 2 = après coupe (Hypothèses B40). Montants relevés dans l'onglet Synthèse pour chaque version.
A4: Compartiment | B4: Version initiale (€) | C4: Après coupe (€) | D4: Écart (€) | E4: Ce que l'on perd
A5: Flotte | B5: 450444 | C5: 344450 | D5: =C5-B5 | E5: 400 vélos achetés au lieu de 600 et 1 060 vélos en flotte au lieu de 1 260. Mais 660 vélos loués : 16 500 € de loyers par mois après le mois 18
A6: Plateforme et outils | B6: 41299 | C6: 39582 | D6: =C6-B6 | E6: Rien : la commission SaaS baisse avec les revenus
A7: RH internes | B7: 240217 | C7: 226683 | D7: =C7-B7 | E7: Un seul technicien du mois 6 au mois 9, pour une flotte qui passe de 300 à plus de 500 vélos : entretien plus lent
A8: Prestations externes | B8: 5200 | C8: 5200 | D8: =C8-B8 | E8: Rien : production du lancement conservée
A9: Média et acquisition | B9: 168132 | C9: 136110 | D9: =C9-B9 | E9: 200 abonnés de moins à recruter, contenus ramenés à 1 000 € par mois
A10: Exploitation | B10: 102302 | C10: 85252 | D10: =C10-B10 | E10: Rien en soi : moins d'abonnés, donc moins d'entretien et d'assurance
A11: Provision pour aléas | B11: 43679 | C11: 41879 | D11: =C11-B11 | E11: Rien : elle n'est pas coupée, elle baisse seule avec la flotte (registre des risques)
A12: Total des coûts | B12: 1051273 | C12: 879157 | D12: =C12-B12 | E12: 86 k€ de revenus en moins sur 18 mois (515 k€ à 429 k€), MRR de 49 000 € au mois 18 au lieu de 58 800 €
A13: Coupe obtenue en % du budget initial | D13: =IF(B12=0,0,D12/B12) | E13: Objectif du DAF : − 15 %
A15: Leviers activés (Hypothèses lignes 64 à 67)
A16: Objectif ramené de 1 200 à 1 000 abonnés | B16: -80523 | E16: Le levier le plus puissant. On perd 86 k€ de revenus et 9 800 € de MRR au mois 18
A17: Plafond d'achat ramené de 600 à 400 vélos | B17: -65034 | E17: Du CAPEX déplacé en OPEX : sur 3 ans, un vélo loué coûte 900 € contre 600 € acheté
A18: 2e technicien embauché au mois 10 au lieu du mois 6 | B18: -13533 | E18: Entretien plus lent pendant 4 mois, risque sur le churn
A19: Création et contenus ramenés de 1 500 à 1 000 € par mois | B19: -8000 | E19: Moins de contenus, acquisition plus dépendante du payant
A20: Effet croisé des leviers | B20: -5023 | E20: Coupe combinée de 172 k€ contre 167 k€ pour la somme des leviers isolés : moins d'abonnés, donc moins de vélos loués
A22: Réponses aux trois questions du DAF
A23: « Pourquoi acheter la flotte plutôt que la louer ? »
A24: Sur 3 ans, un vélo acheté coûte 600 € (16,67 € par mois), un vélo loué 900 € (36 × 25 €). On achète le socle sûr d'être utilisé 3 ans, on loue la partie incertaine, qu'on peut rendre si la montée en charge déçoit.
A25: « Quelle ligne coupez-vous en premier, et que perd-on ? »
A26: L'objectif d'abonnés, de 1 200 à 1 000 : 81 k€ d'économie à lui seul, sans dégrader l'économie unitaire. On perd 86 k€ de revenus sur 18 mois. On ne touche ni à la provision ni au prix d'un abonné.
A27: « Que devient votre point mort si le churn passe à 6 % ? »
A28: Il ne bouge pas : 418 abonnés sans le vélo, 717 avec l'amortissement, car le churn n'entre pas dans la formule. Ce qui change : il faut 119 recrues par mois au lieu de 105 pour le tenir, et la valeur d'un abonné tombe de 583 € à 389 €.

Sheet Scénarios
A1: Stress-test : trois chocs, un par un puis ensemble (bloc 4)
A2: Objectif de 1 200 abonnés maintenu · relevez les résultats de l'onglet Synthèse pour chaque scénario
A4: N° | B4: Scénario | C4: CPC (€) | D4: Mois de lancement | E4: Churn | F4: Coûts (€) | G4: Revenus (€) | H4: Solde (€) | I4: Écart de solde avec la référence (€)
A5: 1 | B5: Référence | C5: =Hypothèses!$B$26 | D5: =Hypothèses!$B$9 | E5: =Hypothèses!$B$10 | F5: 1051273 | G5: 514927 | H5: =G5-F5 | I5: =H5-$H$5
A6: 2 | B6: CPC + 30 % | C6: 1.43 | D6: 4 | E6: 0.04 | F6: 1094512 | G6: 514927 | H6: =G6-F6 | I6: =H6-$H$5
A7: 3 | B7: Plateforme livrée avec 2 mois de retard | C7: 1.1 | D7: 6 | E7: 0.04 | F7: 1014435 | G7: 445047 | H7: =G7-F7 | I7: =H7-$H$5
A8: 4 | B8: Churn à 6 % | C8: 1.1 | D8: 4 | E8: 0.06 | F8: 1083243 | G8: 537355 | H8: =G8-F8 | I8: =H8-$H$5
A9: 5 | B9: Les trois chocs ensemble | C9: 1.43 | D9: 6 | E9: 0.06 | F9: 1086990 | G9: 461992 | H9: =G9-F9 | I9: =H9-$H$5
A11: Méthode : la cellule « scénario actif » (Hypothèses B39) pilote le CPC, le mois de lancement et le churn. Coûts et revenus relevés dans l'onglet Synthèse pour chaque valeur de 1 à 5, puis B39 remis à 1.
A12: Si votre budget contient des chiffres saisis en dur, cet exercice vous oblige à le reconstruire : c'est la raison de la règle du bloc 2.
A14: Hypothèse la plus sensible : le CPC. + 30 % de CPC dégrade le solde de 43 k€, contre 33 k€ pour 2 mois de retard et 10 k€ pour un churn à 6 %.
A15: Le churn pèse peu sur 18 mois : pour tenir 1 200 abonnés on recrute 119 abonnés par mois au lieu de 105, ce qui coûte en média mais rapporte aussi plus tôt.
A16: Son vrai coût arrive après le mois 18 : durée de vie de 16,7 mois au lieu de 25, ratio LTV ÷ CAC de 4,2 au lieu de 6,4 (marge après vélo).
A17: Les trois chocs ensemble dégradent le solde de 89 k€. Les coûts (1 087 k€) restent sous l'enveloppe à 13 k€ près, et l'exploitation n'est jamais positive dans l'horizon.

Sheet Risques
A1: Registre des risques et provision (bloc 4)
A2: Valeur attendue = probabilité × impact · l'impact se calcule dans le tableur, il ne s'estime pas au jugé
A4: Risque | B4: Probabilité | C4: Impact (€) | D4: Valeur attendue (€) | E4: Comment l'impact est calculé, réponse prévue
A5: Vols et casse au-delà de la réserve : 5 % de la flotte à remplacer | B5: 0.3 | C5: ='Budget mensualisé'!$V$9*5%*Hypothèses!$B$11 | D5: =B5*C5 | E5: Flotte du mois 18 × 5 % × 600 €. Réponse : antivols connectés, franchise d'assurance, suivi des vélos
A6: CPC en hausse de 30 % | B6: 0.4 | C6: =-Scénarios!$I$6 | D6: =B6*C6 | E6: Perte de solde du scénario 2 (onglet Scénarios). Réponse : référencement naturel, parrainage, coupe des mots-clés les plus chers
A7: Plateforme livrée avec 2 mois de retard | B7: 0.25 | C7: =-Scénarios!$I$7 | D7: =B7*C7 | E7: Perte de solde du scénario 3. Réponse : SaaS déjà éprouvé, recette dès le mois 2, pénalités de retard au contrat
A8: Churn à 6 % | B8: 0.2 | C8: =-Scénarios!$I$8 | D8: =B8*C8 | E8: Perte de solde du scénario 4. Réponse : enquête de sortie, offre d'engagement à 12 mois, entretien proactif
A9: Intégration du SaaS sous-estimée : 15 jours-homme d'agence | B9: 0.5 | C9: =15*Hypothèses!$B$15 | D9: =B9*C9 | E9: 15 j × 650 €. Réponse : cadrer le paramétrage avec l'éditeur avant de signer
A10: Provision = somme des valeurs attendues | D10: =SUM(D5:D9)
A11: Provision en % du total des coûts | D11: =IF(Synthèse!B12=0,0,D10/Synthèse!B12)
A13: Limite : la valeur attendue est une moyenne. Si un risque se réalise, il coûte son impact entier, pas sa valeur attendue.

Sheet Pilotage M9
A1: Comité de pilotage du mois 9 (bloc 4)
A2: Écarts, décomposition prix et volume, coût à terminaison
A4: Fiche de situation
A5: Abonnés actifs : écart avec le plan | B5: -0.17
A6: Dépenses cumulées : écart avec le plan | B6: 0.09
A7: CPC réel | B7: 1.35
A8: Churn observé | B8: 0.05
A9: Retard de la plateforme (mois) | B9: 1
A10: Jours-homme supplémentaires sur la plateforme | B10: 12
A12: 1. Plan et réel au mois 9
A13: Poste | B13: Plan cumulé à M9 (€) | C13: Réel cumulé à M9 (€) | D13: Écart (€) | E13: Écart (%) | F13: Explication
A14: Flotte | B14: =SUM('Budget mensualisé'!E18:M18) | C14: =SUM(B74:J74) | D14: =C14-B14 | E14: =IF(B14=0,0,D14/B14) | F14: 533 vélos achetés au lieu de 600 : lancement décalé d'un mois et 17 % d'abonnés en moins
A15: Plateforme et outils | B15: =SUM('Budget mensualisé'!E25:M25) | C15: =SUM(B75:J75) | D15: =C15-B15 | E15: =IF(B15=0,0,D15/B15) | F15: 12 jours-homme d'agence en plus (7 800 €), commission SaaS un peu plus faible faute de revenus
A16: RH internes | B16: =SUM('Budget mensualisé'!E30:M30) | C16: =SUM(B76:J76) | D16: =C16-B16 | E16: =IF(B16=0,0,D16/B16) | F16: Équipe recrutée comme prévu
A17: Prestations externes | B17: =SUM('Budget mensualisé'!E33:M33) | C17: =SUM(B79:J79) | D17: =C17-B17 | E17: =IF(B17=0,0,D17/B17) | F17: Production du lancement facturée comme prévu
A18: Média et acquisition | B18: =SUM('Budget mensualisé'!E37:M37) | C18: =SUM(B77:J77) | D18: =C18-B18 | E18: =IF(B18=0,0,D18/B18) | F18: Effet prix + 10,9 k€ (clic à 1,35 € au lieu de 1,10 €), effet volume − 9,8 k€ (moins d'abonnés recrutés)
A19: Exploitation | B19: =SUM('Budget mensualisé'!E41:M41) | C19: =SUM(B78:J78) | D19: =C19-B19 | E19: =IF(B19=0,0,D19/B19) | F19: Moins d'abonnés actifs : moins d'entretien, d'assurance et de frais de paiement
A20: Total | B20: =SUM(B14:B19) | C20: =B20*(1+B6) | D20: =C20-B20 | E20: =IF(B20=0,0,D20/B20) | F20: Réel total = plan × (1 + écart de la fiche)
A21: Écart non expliqué (total − somme des postes) | D21: =D20-SUM(D14:D19) | F21: À faire justifier en comité : les hypothèses de la fiche expliquent une baisse de 39 k€, pas une hausse de 9 %. Pistes : vélos commandés sur le plan, factures hors périmètre, engagements anticipés
A22: Abonnés actifs | B22: ='Budget mensualisé'!M8 | C22: =B22*(1+B5) | D22: =C22-B22
A24: 2. Média : effet prix et effet volume
A25: Clics prévus (acquisitions prévues ÷ conversion) | B25: =SUM('Budget mensualisé'!E6:M6)/Hypothèses!$B$27
A26: CPC prévu | B26: =Hypothèses!$B$70
A27: Clics réels (acquisitions réelles ÷ conversion) | B27: =SUM(B70:J70)/Hypothèses!$B$27
A28: CPC réel | B28: =$B$7
A29: Effet prix = (CPC réel − CPC prévu) × clics réels | B29: =(B28-B26)*B27
A30: Effet volume = (clics réels − clics prévus) × CPC prévu | B30: =(B27-B25)*B26
A31: Écart total du média = effet prix + effet volume | B31: =B29+B30 | C31: =D18-B31 | F31: Contrôle en C31 : écart du poste média − (effet prix + effet volume), doit valoir 0
A33: 3. Coût à terminaison
A34: Poste | B34: Reste à faire réestimé, mois 10 à 18 (€) | F34: Calcul
A35: Flotte | B35: =SUM(K74:S74) | F35: Flotte réestimée : actifs + réserve, achat jusqu'au plafond puis location
A36: Média et acquisition | B36: =SUM(K77:S77) | F36: Nouveaux abonnés réestimés × CAC réel (1,35 € ÷ 1,2 %) + création
A37: RH internes | B37: =SUM(K76:S76) | F37: Inchangé : équipe du plan
A38: Exploitation | B38: =SUM(K78:S78) | F38: Actifs réestimés × 9 € + frais de paiement
A39: Plateforme et outils | B39: =SUM(K75:S75) | F39: SaaS fixe + 2 % du chiffre d'affaires réestimé + outils
A40: Reste à faire | B40: =SUM(B35:B39)
A41: Dépensé à date | B41: =C20
A42: Coût à terminaison = dépensé + reste à faire | B42: =B41+B40
A43: Budget initial | B43: =Synthèse!B12
A44: Écart à terminaison (€) | B44: =B42-B43
...

Sheet BMC
A1: Business Model Canvas (bloc 1, exercice 1)
A2: D'après Osterwalder et Pigneur, Business Model Generation (2010)
A3: 1. Vélora : vente en boutique
A4: Partenaires clés | C4: Activités clés | E4: Proposition de valeur | G4: Relations clients | I4: Segments clients
A5: • Fournisseurs de vélos d'occasion • Fournisseurs de pièces et de batteries • Bailleurs des 6 boutiques • Organisme de paiement en plusieurs fois | C5: • Sourcing et rachat de vélos • Reconditionnement en atelier • Vente et conseil en boutique • SAV ponctuel | E5: • Un vélo électrique de qualité, moins cher que le neuf • Reconditionné et garanti par un pro local • Conseil et essai avant l'achat • Choix écoresponsable : seconde vie | G5: • Transactionnelle : un achat, puis peu de contact • Conseil en face à face • Retour ponctuel au SAV | I5: • Particuliers lyonnais prêts à acheter un vélo électrique • Navetteurs qui veulent un vélo à eux • Sensibles au prix et à l'écologie • Capables d'avancer le prix du vélo
C10: Ressources clés | G10: Canaux
C11: • 6 boutiques à Lyon • Atelier et techniciens • 45 salariés • Stock de vélos à écouler | G11: • Les 6 boutiques • Bouche-à-oreille, notoriété locale • Site vitrine et fiche Google
A16: Structure de coûts | F16: Flux de revenus
A17: • Achat et reconditionnement des vélos : coût variable dominant • Loyers des boutiques, masse salariale • Stock immobilisé, risque d'invendus | F17: • Vente du vélo, encaissée en une fois à l'achat • Accessoires • Réparations facturées à l'acte • Indicateur clé : marge par vélo vendu
A23: 2. Vélora Flex : abonnement
A24: Partenaires clés | C24: Activités clés | E24: Proposition de valeur | G24: Relations clients | I24: Segments clients
A25: • Assureur vol (inclus dans l'offre) • Éditeur SaaS d'abonnement • Prestataire de paiement récurrent • Google Ads et régies • Loueur de vélos (au-delà de 600) | C25: • Gestion de flotte : livraison, retour, remise en état • Acquisition en ligne • Rétention : lutter contre le churn • Entretien inclus, sinistres vol | E25: • Rouler en vélo électrique sans l'acheter • 49 € HT par mois, tout compris : vélo, entretien, assurance vol • Aucune avance pour le client • Zéro souci : panne et vol pris en charge | G25: • Continue : elle dure tant que l'abonnement court • Espace client en ligne • Contacts réguliers pour retenir | I25: • Ceux qui ne veulent pas avancer le prix d'un vélo • Navetteurs urbains, jeunes actifs, étudiants • Ceux qui veulent tester avant d'acheter • Piste : entreprises (forfait mobilités durables)
C30: Ressources clés | G30: Canaux
C31: • Une flotte détenue (600 vélos) et louée • Plateforme SaaS et données clients • Chef de projet, marketing, 2 techniciens • Boutiques en relais | G31: • Vente en ligne • Acquisition payante (CPC 1,10 €) • Boutiques : retrait et entretien
A36: Structure de coûts | F36: Flux de revenus
A37: • Flotte : CAPEX de 600 € par vélo, amorti 16,67 € par mois • Acquisition : 91,67 € par abonné • Entretien et assurance : 9 € par abonné et par mois • SaaS : 1 500 € par mois + 2 % du CA | F37: • Récurrent : 49 € HT par mois • Durée de vie moyenne : 1 ÷ 4 % = 25 mois • MRR visé au mois 18 : 58 800 € HT • Indicateur clé : marge par abonné sur sa durée de vie
A43: Lecture du canvas Vélora Flex
A44: Case orange foncé : change en profondeur
A45: Case jaune clair : change en partie
A46: Ce que ça change pour le budget : la vente encaissée d'un coup devient un revenu étalé, le vélo devient un actif (CAPEX) à financer avant d'encaisser, et le risque passe des invendus au churn, aux vols et à la casse.
